2020-01-23T04:57:56.339858+00:00 heroku[web.1]: Starting process with command `gunicorn flaskr:__init__`
2020-01-23T04:57:59.107559+00:00 app[web.1]: [2020-01-23 04:57:59 +0000] [4] [INFO] Starting gunicorn 19.9.0
2020-01-23T04:57:59.108139+00:00 app[web.1]: [2020-01-23 04:57:59 +0000] [4] [INFO] Listening at: http://0.0.0.0:22950 (4)
2020-01-23T04:57:59.108262+00:00 app[web.1]: [2020-01-23 04:57:59 +0000] [4] [INFO] Using worker: sync
2020-01-23T04:57:59.112629+00:00 app[web.1]: [2020-01-23 04:57:59 +0000] [10] [INFO] Booting worker with pid: 10
2020-01-23T04:57:59.191237+00:00 app[web.1]: [2020-01-23 04:57:59 +0000] [11] [INFO] Booting worker with pid: 11
2020-01-23T04:57:59.261092+00:00 app[web.1]: Failed to find application object '__init__' in 'flaskr'
2020-01-23T04:57:59.261737+00:00 app[web.1]: [2020-01-23 04:57:59 +0000] [10] [INFO] Worker exiting (pid: 10)
2020-01-23T04:57:59.350527+00:00 app[web.1]: Failed to find application object '__init__' in 'flaskr'
2020-01-23T04:57:59.351020+00:00 app[web.1]: [2020-01-23 04:57:59 +0000] [11] [INFO] Worker exiting (pid: 11)
2020-01-23T04:57:59.395800+00:00 app[web.1]: Traceback (most recent call last):
2020-01-23T04:57:59.395819+00:00 app[web.1]: File "/app/.heroku/python/lib/python3.6/site-packages/gunicorn/arbiter.py", line 210, in run
2020-01-23T04:57:59.396189+00:00 app[web.1]: self.sleep()
2020-01-23T04:57:59.396198+00:00 app[web.1]: File "/app/.heroku/python/lib/python3.6/site-packages/gunicorn/arbiter.py", line 360, in sleep
2020-01-23T04:57:59.396528+00:00 app[web.1]: ready = select.select([self.PIPE[0]], [], [], 1.0)
2020-01-23T04:57:59.396535+00:00 app[web.1]: File "/app/.heroku/python/lib/python3.6/site-packages/gunicorn/arbiter.py", line 245, in handle_chld
2020-01-23T04:57:59.396743+00:00 app[web.1]: self.reap_workers()
2020-01-23T04:57:59.396749+00:00 app[web.1]: File "/app/.heroku/python/lib/python3.6/site-packages/gunicorn/arbiter.py", line 528, in reap_workers
2020-01-23T04:57:59.396995+00:00 app[web.1]: raise HaltServer(reason, self.APP_LOAD_ERROR)
2020-01-23T04:57:59.397041+00:00 app[web.1]: gunicorn.errors.HaltServer: <HaltServer 'App failed to load.' 4>
2020-01-23T04:57:59.397048+00:00 app[web.1]: 
2020-01-23T04:57:59.397050+00:00 app[web.1]: During handling of the above exception, another exception occurred:
2020-01-23T04:57:59.397052+00:00 app[web.1]: 
2020-01-23T04:57:59.397057+00:00 app[web.1]: Traceback (most recent call last):
2020-01-23T04:57:59.397061+00:00 app[web.1]: File "/app/.heroku/python/bin/gunicorn", line 11, in <module>
2020-01-23T04:57:59.397193+00:00 app[web.1]: sys.exit(run())
2020-01-23T04:57:59.397199+00:00 app[web.1]: File "/app/.heroku/python/lib/python3.6/site-packages/gunicorn/app/wsgiapp.py", line 61, in run
2020-01-23T04:57:59.397343+00:00 app[web.1]: WSGIApplication("%(prog)s [OPTIONS] [APP_MODULE]").run()
2020-01-23T04:57:59.397349+00:00 app[web.1]: File "/app/.heroku/python/lib/python3.6/site-packages/gunicorn/app/base.py", line 223, in run
2020-01-23T04:57:59.397523+00:00 app[web.1]: super(Application, self).run()
2020-01-23T04:57:59.397529+00:00 app[web.1]: File "/app/.heroku/python/lib/python3.6/site-packages/gunicorn/app/base.py", line 72, in run
2020-01-23T04:57:59.397708+00:00 app[web.1]: Arbiter(self).run()
2020-01-23T04:57:59.397714+00:00 app[web.1]: File "/app/.heroku/python/lib/python3.6/site-packages/gunicorn/arbiter.py", line 232, in run
2020-01-23T04:57:59.397876+00:00 app[web.1]: self.halt(reason=inst.reason, exit_status=inst.exit_status)
2020-01-23T04:57:59.397882+00:00 app[web.1]: File "/app/.heroku/python/lib/python3.6/site-packages/gunicorn/arbiter.py", line 345, in halt
2020-01-23T04:57:59.398121+00:00 app[web.1]: self.stop()
2020-01-23T04:57:59.398128+00:00 app[web.1]: File "/app/.heroku/python/lib/python3.6/site-packages/gunicorn/arbiter.py", line 393, in stop
2020-01-23T04:57:59.398430+00:00 app[web.1]: time.sleep(0.1)
2020-01-23T04:57:59.398436+00:00 app[web.1]: File "/app/.heroku/python/lib/python3.6/site-packages/gunicorn/arbiter.py", line 245, in handle_chld
2020-01-23T04:57:59.398602+00:00 app[web.1]: self.reap_workers()
2020-01-23T04:57:59.398608+00:00 app[web.1]: File "/app/.heroku/python/lib/python3.6/site-packages/gunicorn/arbiter.py", line 528, in reap_workers
2020-01-23T04:57:59.398847+00:00 app[web.1]: raise HaltServer(reason, self.APP_LOAD_ERROR)
2020-01-23T04:57:59.398876+00:00 app[web.1]: gunicorn.errors.HaltServer: <HaltServer 'App failed to load.' 4>
2020-01-23T04:57:59.557621+00:00 heroku[web.1]: State changed from starting to crashed
2020-01-23T04:57:59.540304+00:00 heroku[web.1]: Process exited with status 1
2020-01-23T04:58:06.715141+00:00 heroku[router]: at=error code=H10 desc="App crashed" method=GET path="/" host=shpeportal.herokuapp.com request_id=7115ff9b-9064-41c3-97a6-22e556bfa0e8 fwd="169.234.58.174" dyno= connect= service= status=503 bytes= protocol=https
2020-01-23T04:58:06.862643+00:00 heroku[router]: at=error code=H10 desc="App crashed" method=GET path="/robots.txt" host=shpeportal.herokuapp.com request_id=e9633172-6c35-4022-b801-7f34319f42e5 fwd="169.234.58.174" dyno= connect= service= status=503 bytes= protocol=https
2020-01-23T04:58:07.661102+00:00 heroku[router]: at=error code=H10 desc="App crashed" method=GET path="/favicon.ico" host=shpeportal.herokuapp.com request_id=49227e39-9182-4f4d-aa75-c11df238574a fwd="169.234.58.174" dyno= connect= service= status=503 bytes= protocol=https
2020-01-23T05:02:32.000000+00:00 app[api]: Build started by user tech.shpeuci@gmail.com
2020-01-23T05:03:00.704836+00:00 heroku[web.1]: State changed from crashed to starting
2020-01-23T05:03:00.302335+00:00 app[api]: Deploy e7074bb5 by user tech.shpeuci@gmail.com
2020-01-23T05:03:00.302335+00:00 app[api]: Release v5 created by user tech.shpeuci@gmail.com
2020-01-23T05:03:03.852725+00:00 heroku[web.1]: Starting process with command `gunicorn flaskr:__init__.py`
2020-01-23T05:03:06.481139+00:00 app[web.1]: [2020-01-23 05:03:06 +0000] [4] [INFO] Starting gunicorn 19.9.0
2020-01-23T05:03:06.482312+00:00 app[web.1]: [2020-01-23 05:03:06 +0000] [4] [INFO] Listening at: http://0.0.0.0:43737 (4)
2020-01-23T05:03:06.482533+00:00 app[web.1]: [2020-01-23 05:03:06 +0000] [4] [INFO] Using worker: sync
2020-01-23T05:03:06.497977+00:00 app[web.1]: [2020-01-23 05:03:06 +0000] [10] [INFO] Booting worker with pid: 10
2020-01-23T05:03:06.562907+00:00 app[web.1]: [2020-01-23 05:03:06 +0000] [11] [INFO] Booting worker with pid: 11
2020-01-23T05:03:06.729497+00:00 app[web.1]: Failed to find application object '__init__.py' in 'flaskr'
2020-01-23T05:03:06.730410+00:00 app[web.1]: [2020-01-23 05:03:06 +0000] [10] [INFO] Worker exiting (pid: 10)
2020-01-23T05:03:06.831949+00:00 app[web.1]: Failed to find application object '__init__.py' in 'flaskr'
2020-01-23T05:03:06.831979+00:00 app[web.1]: [2020-01-23 05:03:06 +0000] [11] [INFO] Worker exiting (pid: 11)
2020-01-23T05:03:06.874585+00:00 app[web.1]: Traceback (most recent call last):
2020-01-23T05:03:06.874595+00:00 app[web.1]: File "/app/.heroku/python/lib/python3.6/site-packages/gunicorn/arbiter.py", line 210, in run
2020-01-23T05:03:06.874923+00:00 app[web.1]: self.sleep()
2020-01-23T05:03:06.874930+00:00 app[web.1]: File "/app/.heroku/python/lib/python3.6/site-packages/gunicorn/arbiter.py", line 360, in sleep
2020-01-23T05:03:06.875153+00:00 app[web.1]: ready = select.select([self.PIPE[0]], [], [], 1.0)
2020-01-23T05:03:06.875156+00:00 app[web.1]: File "/app/.heroku/python/lib/python3.6/site-packages/gunicorn/arbiter.py", line 245, in handle_chld
2020-01-23T05:03:06.875334+00:00 app[web.1]: self.reap_workers()
2020-01-23T05:03:06.875340+00:00 app[web.1]: File "/app/.heroku/python/lib/python3.6/site-packages/gunicorn/arbiter.py", line 528, in reap_workers
2020-01-23T05:03:06.875582+00:00 app[web.1]: raise HaltServer(reason, self.APP_LOAD_ERROR)
2020-01-23T05:03:06.875630+00:00 app[web.1]: gunicorn.errors.HaltServer: <HaltServer 'App failed to load.' 4>
2020-01-23T05:03:06.875634+00:00 app[web.1]: 
2020-01-23T05:03:06.875636+00:00 app[web.1]: During handling of the above exception, another exception occurred:
2020-01-23T05:03:06.875638+00:00 app[web.1]: 
2020-01-23T05:03:06.875644+00:00 app[web.1]: Traceback (most recent call last):
2020-01-23T05:03:06.875648+00:00 app[web.1]: File "/app/.heroku/python/bin/gunicorn", line 11, in <module>
2020-01-23T05:03:06.875778+00:00 app[web.1]: sys.exit(run())
2020-01-23T05:03:06.875784+00:00 app[web.1]: File "/app/.heroku/python/lib/python3.6/site-packages/gunicorn/app/wsgiapp.py", line 61, in run
2020-01-23T05:03:06.875954+00:00 app[web.1]: WSGIApplication("%(prog)s [OPTIONS] [APP_MODULE]").run()
2020-01-23T05:03:06.875958+00:00 app[web.1]: File "/app/.heroku/python/lib/python3.6/site-packages/gunicorn/app/base.py", line 223, in run
2020-01-23T05:03:06.876131+00:00 app[web.1]: super(Application, self).run()
2020-01-23T05:03:06.876134+00:00 app[web.1]: File "/app/.heroku/python/lib/python3.6/site-packages/gunicorn/app/base.py", line 72, in run
2020-01-23T05:03:06.876272+00:00 app[web.1]: Arbiter(self).run()
2020-01-23T05:03:06.876275+00:00 app[web.1]: File "/app/.heroku/python/lib/python3.6/site-packages/gunicorn/arbiter.py", line 232, in run
2020-01-23T05:03:06.876443+00:00 app[web.1]: self.halt(reason=inst.reason, exit_status=inst.exit_status)
2020-01-23T05:03:06.876447+00:00 app[web.1]: File "/app/.heroku/python/lib/python3.6/site-packages/gunicorn/arbiter.py", line 345, in halt
2020-01-23T05:03:06.876649+00:00 app[web.1]: self.stop()
2020-01-23T05:03:06.876652+00:00 app[web.1]: File "/app/.heroku/python/lib/python3.6/site-packages/gunicorn/arbiter.py", line 393, in stop
2020-01-23T05:03:06.876862+00:00 app[web.1]: time.sleep(0.1)
2020-01-23T05:03:06.876865+00:00 app[web.1]: File "/app/.heroku/python/lib/python3.6/site-packages/gunicorn/arbiter.py", line 245, in handle_chld
2020-01-23T05:03:06.877035+00:00 app[web.1]: self.reap_workers()
2020-01-23T05:03:06.877041+00:00 app[web.1]: File "/app/.heroku/python/lib/python3.6/site-packages/gunicorn/arbiter.py", line 528, in reap_workers
2020-01-23T05:03:06.877283+00:00 app[web.1]: raise HaltServer(reason, self.APP_LOAD_ERROR)
2020-01-23T05:03:06.877311+00:00 app[web.1]: gunicorn.errors.HaltServer: <HaltServer 'App failed to load.' 4>
2020-01-23T05:03:06.984704+00:00 heroku[web.1]: State changed from starting to crashed
2020-01-23T05:03:06.961338+00:00 heroku[web.1]: Process exited with status 1
2020-01-23T05:03:08.000000+00:00 app[api]: Build succeeded
2020-01-23T05:03:13.917831+00:00 heroku[router]: at=error code=H10 desc="App crashed" method=GET path="/" host=shpeportal.herokuapp.com request_id=a49b5d1f-cc6f-46c8-bc70-aec07a438a32 fwd="169.234.58.174" dyno= connect= service= status=503 bytes= protocol=https
2020-01-23T05:03:14.743781+00:00 heroku[router]: at=error code=H10 desc="App crashed" method=GET path="/favicon.ico" host=shpeportal.herokuapp.com request_id=9ed26016-76e8-4d28-80b2-74bb28c12aae fwd="169.234.58.174" dyno= connect= service= status=503 bytes= protocol=https
